<?xml version="1.0" ?>
<robot name="klaw" xmlns:xacro="http://www.ros.org/wiki/xacro">

<xacro:include filename="$(find klaw_description)/urdf/klaw.trans" />
<xacro:include filename="$(find klaw_description)/urdf/klaw.gazebo" />
<xacro:include filename="$(find klaw_description)/urdf/ros2_control.xacro" />



<link name="world">
  
</link>

<link name="base_link">
  <inertial>
    <origin xyz="-1.421102024076207e-17 1.705322428891448e-16 0.07306351340337607" rpy="0 0 0"/>
    <mass value="40.19153185603866"/>
    <inertia ixx="0.203171" iyy="0.203171" izz="0.21854" ixy="0.0" iyz="0.0" ixz="0.0"/>
  </inertial>
  <visual>
    <origin xyz="0 0 0" rpy="0 0 0"/>
    <geometry>
      <mesh filename="file://$(find klaw_description)/meshes/base_link.stl" scale="0.001 0.001 0.001"/>
    </geometry>
    
  </visual>
  <collision>
    <origin xyz="0 0 0" rpy="0 0 0"/>
    <geometry>
      <mesh filename="file://$(find klaw_description)/meshes/base_link.stl" scale="0.001 0.001 0.001"/>
    </geometry>
  </collision>
</link>

<link name="link_1_1">
  <inertial>
    <origin xyz="-0.008568133783517345 -3.0846065489217774e-10 0.5062319769790291" rpy="0 0 0"/>
    <mass value="147.52880907576287"/>
    <inertia ixx="11.265871" iyy="11.463489" izz="0.620107" ixy="-0.0" iyz="0.0" ixz="0.371336"/>
  </inertial>
  <visual>
    <origin xyz="-0.0 -0.0 -0.175" rpy="0 0 0"/>
    <geometry>
      <mesh filename="file://$(find klaw_description)/meshes/link_1_1.stl" scale="0.001 0.001 0.001"/>
    </geometry>
    
  </visual>
  <collision>
    <origin xyz="-0.0 -0.0 -0.175" rpy="0 0 0"/>
    <geometry>
      <mesh filename="file://$(find klaw_description)/meshes/link_1_1.stl" scale="0.001 0.001 0.001"/>
    </geometry>
  </collision>
</link>

<link name="link_2_1">
  <inertial>
    <origin xyz="0.1245512062311353 -2.921145237181765e-10 -0.05827343033394239" rpy="0 0 0"/>
    <mass value="71.96980119016024"/>
    <inertia ixx="0.930857" iyy="1.052856" izz="0.333158" ixy="0.0" iyz="0.0" ixz="0.001882"/>
  </inertial>
  <visual>
    <origin xyz="-0.1 -0.0 -0.975" rpy="0 0 0"/>
    <geometry>
      <mesh filename="file://$(find klaw_description)/meshes/link_2_1.stl" scale="0.001 0.001 0.001"/>
    </geometry>
    
  </visual>
  <collision>
    <origin xyz="-0.1 -0.0 -0.975" rpy="0 0 0"/>
    <geometry>
      <mesh filename="file://$(find klaw_description)/meshes/link_2_1.stl" scale="0.001 0.001 0.001"/>
    </geometry>
  </collision>
</link>

<link name="link_3_1">
  <inertial>
    <origin xyz="-0.0041687451639426665 2.4490892518297913e-10 -0.28296834081957944" rpy="0 0 0"/>
    <mass value="85.84189361506444"/>
    <inertia ixx="2.011883" iyy="2.093209" izz="0.3315" ixy="0.0" iyz="0.0" ixz="-0.04188"/>
  </inertial>
  <visual>
    <origin xyz="-0.225 0.0 -0.7" rpy="0 0 0"/>
    <geometry>
      <mesh filename="file://$(find klaw_description)/meshes/link_3_1.stl" scale="0.001 0.001 0.001"/>
    </geometry>
    
  </visual>
  <collision>
    <origin xyz="-0.225 0.0 -0.7" rpy="0 0 0"/>
    <geometry>
      <mesh filename="file://$(find klaw_description)/meshes/link_3_1.stl" scale="0.001 0.001 0.001"/>
    </geometry>
  </collision>
</link>

<link name="link_4_1">
  <inertial>
    <origin xyz="0.1638545267815762 2.1843498479966732e-10 0.10438066960167053" rpy="0 0 0"/>
    <mass value="96.24596491081947"/>
    <inertia ixx="2.168239" iyy="2.426049" izz="0.537245" ixy="-0.0" iyz="0.0" ixz="-0.11197"/>
  </inertial>
  <visual>
    <origin xyz="-0.325 -0.0 -0.3" rpy="0 0 0"/>
    <geometry>
      <mesh filename="file://$(find klaw_description)/meshes/link_4_1.stl" scale="0.001 0.001 0.001"/>
    </geometry>
    
  </visual>
  <collision>
    <origin xyz="-0.325 -0.0 -0.3" rpy="0 0 0"/>
    <geometry>
      <mesh filename="file://$(find klaw_description)/meshes/link_4_1.stl" scale="0.001 0.001 0.001"/>
    </geometry>
  </collision>
</link>

<link name="link_5_1">
  <inertial>
    <origin xyz="-0.0032327309338666677 3.1210920990032796e-10 0.21836403161802154" rpy="0 0 0"/>
    <mass value="74.05061270784716"/>
    <inertia ixx="0.943577" iyy="1.097431" izz="0.370865" ixy="0.0" iyz="-0.0" ixz="0.013558"/>
  </inertial>
  <visual>
    <origin xyz="-0.5 -0.0 -0.7" rpy="0 0 0"/>
    <geometry>
      <mesh filename="file://$(find klaw_description)/meshes/link_5_1.stl" scale="0.001 0.001 0.001"/>
    </geometry>
    
  </visual>
  <collision>
    <origin xyz="-0.5 -0.0 -0.7" rpy="0 0 0"/>
    <geometry>
      <mesh filename="file://$(find klaw_description)/meshes/link_5_1.stl" scale="0.001 0.001 0.001"/>
    </geometry>
  </collision>
</link>

<link name="gripper">
  <inertial>
    <origin xyz="0.12302924828385442 -1.384668828843036e-16 3.842416607113819e-09" rpy="0 0 0"/>
    <mass value="41.24904531797942"/>
    <inertia ixx="0.345961" iyy="0.275637" izz="0.42382" ixy="0.0" iyz="-0.0" ixz="0.0"/>
  </inertial>
  <visual>
    <origin xyz="-0.625 0.0 -0.975" rpy="0 0 0"/>
    <geometry>
      <mesh filename="file://$(find klaw_description)/meshes/gripper_1.stl" scale="0.001 0.001 0.001"/>
    </geometry>
    
  </visual>
  <collision>
    <origin xyz="-0.625 0.0 -0.975" rpy="0 0 0"/>
    <geometry>
      <mesh filename="file://$(find klaw_description)/meshes/gripper_1.stl" scale="0.001 0.001 0.001"/>
    </geometry>
  </collision>
</link>

<link name="klaw_1_1">
  <inertial>
    <origin xyz="0.10907996202263937 0.03079606649729505 0.0" rpy="0 0 0"/>
    <mass value="9.825408837386393"/>
    <inertia ixx="0.021616" iyy="0.06969" izz="0.080826" ixy="-0.025759" iyz="0.0" ixz="0.0"/>
  </inertial>
  <visual>
    <origin xyz="-0.84 0.13 -0.975" rpy="0 0 0"/>
    <geometry>
      <mesh filename="file://$(find klaw_description)/meshes/klaw_1_1.stl" scale="0.001 0.001 0.001"/>
    </geometry>
    
  </visual>
  <collision>
    <origin xyz="-0.84 0.13 -0.975" rpy="0 0 0"/>
    <geometry>
      <mesh filename="file://$(find klaw_description)/meshes/klaw_1_1.stl" scale="0.001 0.001 0.001"/>
    </geometry>
  </collision>
</link>

<link name="klaw_2_1">
  <inertial>
    <origin xyz="0.10907996202263914 -0.030796066497295174 -1.1102230246251565e-16" rpy="0 0 0"/>
    <mass value="9.825408837386401"/>
    <inertia ixx="0.021616" iyy="0.06969" izz="0.080826" ixy="0.025759" iyz="-0.0" ixz="-0.0"/>
  </inertial>
  <visual>
    <origin xyz="-0.84 -0.13 -0.975" rpy="0 0 0"/>
    <geometry>
      <mesh filename="file://$(find klaw_description)/meshes/klaw_2_1.stl" scale="0.001 0.001 0.001"/>
    </geometry>
    
  </visual>
  <collision>
    <origin xyz="-0.84 -0.13 -0.975" rpy="0 0 0"/>
    <geometry>
      <mesh filename="file://$(find klaw_description)/meshes/klaw_2_1.stl" scale="0.001 0.001 0.001"/>
    </geometry>
  </collision>
</link>

<joint name="world_joint" type="fixed">
  <origin xyz="0.0 0.0 0.55" rpy="0 0 0"/>
  <parent link="world"/>
  <child link="base_link"/>
</joint>

<joint name="joint_1" type="continuous">
  <origin xyz="0.0 0.0 0.175" rpy="0 0 0"/>
  <parent link="base_link"/>
  <child link="link_1_1"/>
  <axis xyz="0.0 0.0 1.0"/>
</joint>

<joint name="joint_2" type="continuous">
  <origin xyz="0.1 0.0 0.8" rpy="0 0 0"/>
  <parent link="link_1_1"/>
  <child link="link_2_1"/>
  <axis xyz="1.0 0.0 0.0"/>
</joint>

<joint name="joint_3" type="continuous">
  <origin xyz="0.125 -0.0 -0.275" rpy="0 0 0"/>
  <parent link="link_2_1"/>
  <child link="link_3_1"/>
  <axis xyz="0.0 0.0 -1.0"/>
</joint>

<joint name="joint_4" type="continuous">
  <origin xyz="0.1 0.0 -0.4" rpy="0 0 0"/>
  <parent link="link_3_1"/>
  <child link="link_4_1"/>
  <axis xyz="1.0 0.0 0.0"/>
</joint>

<joint name="joint_5" type="continuous">
  <origin xyz="0.175 0.0 0.4" rpy="0 0 0"/>
  <parent link="link_4_1"/>
  <child link="link_5_1"/>
  <axis xyz="0.0 0.0 1.0"/>
</joint>

<joint name="joint_6" type="continuous">
  <origin xyz="0.125 -0.0 0.275" rpy="0 0 0"/>
  <parent link="link_5_1"/>
  <child link="gripper"/>
  <axis xyz="1.0 0.0 0.0"/>
</joint>

<joint name="gripper_1" type="revolute">
  <origin xyz="0.215 -0.13 0.0" rpy="0 0 0"/>
  <parent link="gripper"/>
  <child link="klaw_1_1"/>
  <axis xyz="0.0 0.0 1.0"/>
  <limit upper="0.0" lower="-3.228859" effort="100" velocity="100"/>
</joint>

<joint name="gripper_2" type="revolute">
  <origin xyz="0.215 0.13 0.0" rpy="6.283185 0 0"/>
  <parent link="gripper"/>
  <child link="klaw_2_1"/>
  <axis xyz="0.0 0.0 -1.0"/>
  <!-- <limit upper="6.283185" lower="3.228859" effort="100" velocity="100"/> -->
  <limit upper="0" lower="-3.228859" effort="100" velocity="100"/>
</joint>

</robot>
